Workbook

Sheet Demand Planning20230927
A1: R/D | AD1: need | AE1: =(AE3+AE5)/(AE4/5) -> 2.5 | AF1: =(AF3+AF5)/(AF4/5) -> 2.9166667 | AG1: =(AG3+AG5)/(AG4/5) -> 2.5 | AH1: =(AH3+AH5)/(AH4/5) -> 2.7272727 | AI1: =(AI3+AI5)/(AI4/5) -> 3.5416667 | AJ1: =(AJ3+AJ5)/(AJ4/5) -> 4.1666667 | AK1: =(AK3+AK5)/(AK4/5) -> 9.0625 | AL1: =(AL3+AL5)/(AL4/5) -> 4.0909091
A2: COMBINED | AD2: days sch | AE2: =AE3/(AE4/5) -> 2.5 | AF2: =AF3/(AF4/5) -> 2.9166667 | AG2: =AG3/(AG4/5) -> 2 | AH2: =AH3/(AH4/5) -> 1.8181818 | AI2: =AI3/(AI4/5) -> 0.625 | AJ2: =AJ3/(AJ4/5) -> 2.9166667 | AK2: =AK3/(AK4/5) -> 5.9375 | AL2: =AL3/(AL4/5) -> 3.6363636
A3: NEED GR | AA3: Add Total Jobs currently scheduled -> | AD3: current | AE3: 6 | AF3: 7 | AG3: 4 | AH3: 4 | AI3: 1.5 | AJ3: 7 | AK3: 9.5 | AL3: 8
A4: NO GREIGE | AD4: Weekly Turns | AE4: 12 | AF4: 12 | AG4: 10 | AH4: 11 | AI4: 12 | AJ4: 12 | AK4: 8 | AL4: 11
A5: MISSING OR INCORRECT INFO | AD5: # sch | AE5: =SUM(AE9:AE104) -> 0 | AF5: =SUM(AF9:AF104) -> 0 | AG5: =SUM(AG9:AG104) -> 1 | AH5: =SUM(AH9:AH104) -> 2 | AI5: =SUM(AI9:AI104) -> 7 | AJ5: =SUM(AJ9:AJ104) -> 3 | AK5: =SUM(AK9:AK104) -> 5 | AL5: =SUM(AL9:AL104) -> 1
A6: ALLOCATED | AD6: # greige rolls | AE6: 1 | AF6: 1 | AG6: 1 | AH6: 2 | AI6: 3 | AJ6: 4 | AK6: 4 | AL6: 4
A7: CONVERT LAST
A8: Plant | B8: item | C8: desc | D8: PA Fin Item | E8: PA WIP Item | F8: Yield | G8: PA Qty | H8: Adaptive Qty | I8: P1 Demand | J8: P2 Demand | K8: P3 Demand | L8: P4 Demand | M8: P1 New | N8: P2 New | O8: P3 New | P8: P4 New | Q8: 45882 | R8: 45883 | S8: 45884 | T8: 45887 | U8: Grand Total | V8: 45241 | W8: 45242 | X8: (blank) | Y8: Yield/greige | Z8: Greige | AA8: Week 2 Order | AB8: Lot Size | AC8: Bal to Sch | AD8: excess jobs | AE8: Jet-01 | AF8: Jet-02 | AG8: Jet-03 | AH8: Jet-04 | AI8: Jet-07 | AJ8: Jet-08 | AK8: Jet-09 | AL8: Jet-10 | AM8: Total lbs Sch | AN8: BAL TO SCH | AO8: Notes
A9: 50 | B9: 210189A | C9: AURA30000/DX9/BLK/63 | D9: FF AURA30000-39064-63 | E9: FF AURA30000-39064-126 | F9: 2.5904762 | G9: 10834 | I9: 3710 | J9: 9646 | K9: 0 | L9: 9010 | M9: 0 | N9: 2522 | O9: 0 | P9: 9010 | Q9: =IFERROR(VLOOKUP($E9,Adaptive!$A:$J,MATCH(Q$8,Adaptive!$4:$4,0),FALSE),0) -> 0 | R9: =IFERROR(VLOOKUP($E9,Adaptive!$A:$J,MATCH(R$8,Adaptive!$4:$4,0),FALSE),0) -> 0 | S9: =IFERROR(VLOOKUP($E9,Adaptive!$A:$J,MATCH(S$8,Adaptive!$4:$4,0),FALSE),0) -> 0 | T9: =IFERROR(VLOOKUP($E9,Adaptive!$A:$J,MATCH(T$8,Adaptive!$4:$4,0),FALSE),0) -> 0 | U9: =IFERROR(VLOOKUP($E9,Adaptive!$A:$J,MATCH(U$8,Adaptive!$4:$4,0),FALSE),0) -> 0 | V9: =IFERROR(VLOOKUP($E9,Adaptive!$A:$J,MATCH(V$8,Adaptive!$4:$4,0),FALSE),0) -> 0 | W9: =IFERROR(VLOOKUP($E9,Adaptive!$A:$J,MATCH(W$8,Adaptive!$4:$4,0),FALSE),0) -> 0 | X9: =IFERROR(VLOOKUP($E9,Adaptive!$A:$J,MATCH(X$8,Adaptive!$4:$4,0),FALSE),0) -> 0 | Y9: =F9*700 -> 1813.3333 | Z9: =_xlfn.XLOOKUP(B9,[1]Xref!$H:$H,[1]Xref!$A:$A) -> AU2958G | AA9: =SUM(M9:P9) -> 11532 | AB9: =ROUNDUP(AA9/Y9,0) -> 7 | AC9: =AB9-SUMPRODUCT(AE9:AL9,$AE$6:$AL$6) -> 3 | AK9: 1 | AM9: =SUMPRODUCT(AE9:AL9,$AE$6:$AL$6)*700 -> 2800 | AN9: =AC9*700 -> 2100
A10: 50 | B10: 220010A | C10: TAFFETAGMW/9874/LAG/63 | D10: FF TAFFETAGMW-39329-63 | E10: FF TAFFETAGMW-39329-189 | F10: 2.1587301587301586 | I10: 0 | J10: 0 | K10: 0 | L10: 0 | M10: 0 | N10: 0 | O10: 0 | P10: 0 | Q10: =IFERROR(VLOOKUP($E10,Adaptive!$A:$J,MATCH(Q$8,Adaptive!$4:$4,0),FALSE),0) -> 0 | R10: =IFERROR(VLOOKUP($E10,Adaptive!$A:$J,MATCH(R$8,Adaptive!$4:$4,0),FALSE),0) -> 0 | S10: =IFERROR(VLOOKUP($E10,Adaptive!$A:$J,MATCH(S$8,Adaptive!$4:$4,0),FALSE),0) -> 0 | T10: =IFERROR(VLOOKUP($E10,Adaptive!$A:$J,MATCH(T$8,Adaptive!$4:$4,0),FALSE),0) -> 0 | U10: =IFERROR(VLOOKUP($E10,Adaptive!$A:$J,MATCH(U$8,Adaptive!$4:$4,0),FALSE),0) -> 0 | V10: =IFERROR(VLOOKUP($E10,Adaptive!$A:$J,MATCH(V$8,Adaptive!$4:$4,0),FALSE),0) -> 0 | W10: =IFERROR(VLOOKUP($E10,Adaptive!$A:$J,MATCH(W$8,Adaptive!$4:$4,0),FALSE),0) -> 0 | X10: =IFERROR(VLOOKUP($E10,Adaptive!$A:$J,MATCH(X$8,Adaptive!$4:$4,0),FALSE),0) -> 0 | Y10: =F10*700 -> 1511.1111 | Z10: =_xlfn.XLOOKUP(B10,[1]Xref!$H:$H,[1]Xref!$A:$A) -> AU4583 210 | AA10: =SUM(M10:P10) -> 0 | AB10: =ROUNDUP(AA10/Y10,0) -> 0 | AC10: =AB10-SUMPRODUCT(AE10:AL10,$AE$6:$AL$6) -> 0 | AM10: =SUMPRODUCT(AE10:AL10,$AE$6:$AL$6)*700 -> 0 | AN10: =AC10*700 -> 0
A11: 50 | B11: 222127 | C11: TAFFETA/600R/JT BLK/60 | D11: FF TAFFETAHP-38712-60 | E11: FF TAFFETAHP-38712-180 | F11: 2.2666666666666666 | I11: 429 | J11: 0 | K11: 0 | L11: 1717 | M11: 429 | N11: 0 | O11: 0 | P11: 1717 | Q11: =IFERROR(VLOOKUP($E11,Adaptive!$A:$J,MATCH(Q$8,Adaptive!$4:$4,0),FALSE),0) -> 0 | R11: =IFERROR(VLOOKUP($E11,Adaptive!$A:$J,MATCH(R$8,Adaptive!$4:$4,0),FALSE),0) -> 0 | S11: =IFERROR(VLOOKUP($E11,Adaptive!$A:$J,MATCH(S$8,Adaptive!$4:$4,0),FALSE),0) -> 0 | T11: =IFERROR(VLOOKUP($E11,Adaptive!$A:$J,MATCH(T$8,Adaptive!$4:$4,0),FALSE),0) -> 0 | U11: =IFERROR(VLOOKUP($E11,Adaptive!$A:$J,MATCH(U$8,Adaptive!$4:$4,0),FALSE),0) -> 0 | V11: =IFERROR(VLOOKUP($E11,Adaptive!$A:$J,MATCH(V$8,Adaptive!$4:$4,0),FALSE),0) -> 0 | W11: =IFERROR(VLOOKUP($E11,Adaptive!$A:$J,MATCH(W$8,Adaptive!$4:$4,0),FALSE),0) -> 0 | X11: =IFERROR(VLOOKUP($E11,Adaptive!$A:$J,MATCH(X$8,Adaptive!$4:$4,0),FALSE),0) -> 0 | Y11: =F11*700 -> 1586.6667 | Z11: =_xlfn.XLOOKUP(B11,[1]Xref!$H:$H,[1]Xref!$A:$A) -> AU4583 210 | AA11: =SUM(M11:P11) -> 2146 | AB11: =ROUNDUP(AA11/Y11,0) -> 2 | AC11: =AB11-SUMPRODUCT(AE11:AL11,$AE$6:$AL$6) -> 2 | AM11: =SUMPRODUCT(AE11:AL11,$AE$6:$AL$6)*700 -> 0 | AN11: =AC11*700 -> 1400
A12: 50 | B12: 223566 | C12: AU3426M/ME/LT GR/62 | D12: FF AU3426M-38840-62 | E12: FF AU3426M-38840-124 | F12: 2.632258064516129 | G12: 6756 | I12: 22447 | J12: 2683 | K12: 23637 | L12: 0 | M12: 15691 | N12: 2683 | O12: 23637 | P12: 0 | Q12: =IFERROR(VLOOKUP($E12,Adaptive!$A:$J,MATCH(Q$8,Adaptive!$4:$4,0),FALSE),0) -> 0 | R12: =IFERROR(VLOOKUP($E12,Adaptive!$A:$J,MATCH(R$8,Adaptive!$4:$4,0),FALSE),0) -> 0 | S12: =IFERROR(VLOOKUP($E12,Adaptive!$A:$J,MATCH(S$8,Adaptive!$4:$4,0),FALSE),0) -> 0 | T12: =IFERROR(VLOOKUP($E12,Adaptive!$A:$J,MATCH(T$8,Adaptive!$4:$4,0),FALSE),0) -> 0 | U12: =IFERROR(VLOOKUP($E12,Adaptive!$A:$J,MATCH(U$8,Adaptive!$4:$4,0),FALSE),0) -> 0 | V12: =IFERROR(VLOOKUP($E12,Adaptive!$A:$J,MATCH(V$8,Adaptive!$4:$4,0),FALSE),0) -> 0 | W12: =IFERROR(VLOOKUP($E12,Adaptive!$A:$J,MATCH(W$8,Adaptive!$4:$4,0),FALSE),0) -> 0 | X12: =IFERROR(VLOOKUP($E12,Adaptive!$A:$J,MATCH(X$8,Adaptive!$4:$4,0),FALSE),0) -> 0 | Y12: =F12*700 -> 1842.5806 | Z12: =_xlfn.XLOOKUP(B12,[1]Xref!$H:$H,[1]Xref!$A:$A) -> AU3426 Wide | AA12: =SUM(M12:P12) -> 42011 | AB12: =ROUNDUP(AA12/Y12,0) -> 23 | AC12: =AB12-SUMPRODUCT(AE12:AL12,$AE$6:$AL$6) -> 23 | AM12: =SUMPRODUCT(AE12:AL12,$AE$6:$AL$6)*700 -> 0 | AN12: =AC12*700 -> 16100
A13: 50 | B13: 225786 | C13: AU3426M/ME/LT GR/73 | D13: FF AU3426M-38840-73 | E13: FF AU3426M-38840-146 | F13: 2.2356164383561645 | I13: 0 | J13: 200 | K13: 0 | L13: 0 | M13: 0 | N13: 0 | O13: 0 | P13: 0 | Q13: =IFERROR(VLOOKUP($E13,Adaptive!$A:$J,MATCH(Q$8,Adaptive!$4:$4,0),FALSE),0) -> 0 | R13: =IFERROR(VLOOKUP($E13,Adaptive!$A:$J,MATCH(R$8,Adaptive!$4:$4,0),FALSE),0) -> 0 | S13: =IFERROR(VLOOKUP($E13,Adaptive!$A:$J,MATCH(S$8,Adaptive!$4:$4,0),FALSE),0) -> 0 | T13: =IFERROR(VLOOKUP($E13,Adaptive!$A:$J,MATCH(T$8,Adaptive!$4:$4,0),FALSE),0) -> 0 | U13: =IFERROR(VLOOKUP($E13,Adaptive!$A:$J,MATCH(U$8,Adaptive!$4:$4,0),FALSE),0) -> 0 | V13: =IFERROR(VLOOKUP($E13,Adaptive!$A:$J,MATCH(V$8,Adaptive!$4:$4,0),FALSE),0) -> 0 | W13: =IFERROR(VLOOKUP($E13,Adaptive!$A:$J,MATCH(W$8,Adaptive!$4:$4,0),FALSE),0) -> 0 | X13: =IFERROR(VLOOKUP($E13,Adaptive!$A:$J,MATCH(X$8,Adaptive!$4:$4,0),FALSE),0) -> 0 | Y13: =F13*700 -> 1564.9315 | Z13: =_xlfn.XLOOKUP(B13,[1]Xref!$H:$H,[1]Xref!$A:$A) -> AU3426 | AA13: =SUM(M13:P13) -> 0 | AB13: =ROUNDUP(AA13/Y13,0) -> 0 | AC13: =AB13-SUMPRODUCT(AE13:AL13,$AE$6:$AL$6) -> 0 | AM13: =SUMPRODUCT(AE13:AL13,$AE$6:$AL$6)*700 -> 0 | AN13: =AC13*700 -> 0
A14: 50 | B14: 226042 | C14: TAFFETA/PACCAR GRAY/65 | D14: FF TAFFETAHP-39869-65 | E14: FF TAFFETAHP-39869-130 | F14: 2.0923076923076924 | G14: 250 | I14: 0 | J14: 0 | K14: 0 | L14: 212 | M14: 0 | N14: 0 | O14: 0 | P14: 0 | Q14: =IFERROR(VLOOKUP($E14,Adaptive!$A:$J,MATCH(Q$8,Adaptive!$4:$4,0),FALSE),0) -> 0 | R14: =IFERROR(VLOOKUP($E14,Adaptive!$A:$J,MATCH(R$8,Adaptive!$4:$4,0),FALSE),0) -> 0 | S14: =IFERROR(VLOOKUP($E14,Adaptive!$A:$J,MATCH(S$8,Adaptive!$4:$4,0),FALSE),0) -> 0 | T14: =IFERROR(VLOOKUP($E14,Adaptive!$A:$J,MATCH(T$8,Adaptive!$4:$4,0),FALSE),0) -> 0 | U14: =IFERROR(VLOOKUP($E14,Adaptive!$A:$J,MATCH(U$8,Adaptive!$4:$4,0),FALSE),0) -> 0 | V14: =IFERROR(VLOOKUP($E14,Adaptive!$A:$J,MATCH(V$8,Adaptive!$4:$4,0),FALSE),0) -> 0 | W14: =IFERROR(VLOOKUP($E14,Adaptive!$A:$J,MATCH(W$8,Adaptive!$4:$4,0),FALSE),0) -> 0 | X14: =IFERROR(VLOOKUP($E14,Adaptive!$A:$J,MATCH(X$8,Adaptive!$4:$4,0),FALSE),0) -> 0 | Y14: =F14*700 -> 1464.6154 | Z14: =_xlfn.XLOOKUP(B14,[1]Xref!$H:$H,[1]Xref!$A:$A) -> AU4583 | AA14: =SUM(M14:P14) -> 0 | AB14: =ROUNDUP(AA14/Y14,0) -> 0 | AC14: =AB14-SUMPRODUCT(AE14:AL14,$AE$6:$AL$6) -> 0 | AM14: =SUMPRODUCT(AE14:AL14,$AE$6:$AL$6)*700 -> 0 | AN14: =AC14*700 -> 0
A15: 12 | B15: 227208A | C15: TR570BD/NH836L/WSGR/66 | D15: FF TR570B-D-39226-66 | E15: FF TR570B-D-39226-132 | F15: 1.8545454545454547 | G15: 233 | I15: 47 | M15: 0 | N15: 0 | O15: 0 | P15: 0 | Q15: =IFERROR(VLOOKUP($E15,Adaptive!$A:$J,MATCH(Q$8,Adaptive!$4:$4,0),FALSE),0) -> 0 | R15: =IFERROR(VLOOKUP($E15,Adaptive!$A:$J,MATCH(R$8,Adaptive!$4:$4,0),FALSE),0) -> 0 | S15: =IFERROR(VLOOKUP($E15,Adaptive!$A:$J,MATCH(S$8,Adaptive!$4:$4,0),FALSE),0) -> 0 | T15: =IFERROR(VLOOKUP($E15,Adaptive!$A:$J,MATCH(T$8,Adaptive!$4:$4,0),FALSE),0) -> 0 | U15: =IFERROR(VLOOKUP($E15,Adaptive!$A:$J,MATCH(U$8,Adaptive!$4:$4,0),FALSE),0) -> 0 | V15: =IFERROR(VLOOKUP($E15,Adaptive!$A:$J,MATCH(V$8,Adaptive!$4:$4,0),FALSE),0) -> 0 | W15: =IFERROR(VLOOKUP($E15,Adaptive!$A:$J,MATCH(W$8,Adaptive!$4:$4,0),FALSE),0) -> 0 | X15: =IFERROR(VLOOKUP($E15,Adaptive!$A:$J,MATCH(X$8,Adaptive!$4:$4,0),FALSE),0) -> 0 | Y15: =F15*700 -> 1298.1818 | Z15: =_xlfn.XLOOKUP(B15,[1]Xref!$H:$H,[1]Xref!$A:$A) -> AU7529 | AA15: =SUM(M15:P15) -> 0 | AB15: =ROUNDUP(AA15/Y15,0) -> 0 | AC15: =AB15-SUMPRODUCT(AE15:AL15,$AE$6:$AL$6) -> 0 | AM15: =SUMPRODUCT(AE15:AL15,$AE$6:$AL$6)*700 -> 0 | AN15: =AC15*700 -> 0
A16: 1250 | B16: 227469 | C16: AU3426M/ME/LT GR/64 | D16: FF AU3426M-38840-64 | E16: FF AU3426M-38840-128 | F16: 2.55 | G16: 4181 | H16: 7998 | I16: 6197 | J16: 1101 | K16: 4158 | L16: 0 | M16: 0 | N16: 0 | O16: 0 | P16: 0 | Q16: =IFERROR(VLOOKUP($E16,Adaptive!$A:$J,MATCH(Q$8,Adaptive!$4:$4,0),FALSE),0) -> 0 | R16: =IFERROR(VLOOKUP($E16,Adaptive!$A:$J,MATCH(R$8,Adaptive!$4:$4,0),FALSE),0) -> 7998 | S16: =IFERROR(VLOOKUP($E16,Adaptive!$A:$J,MATCH(S$8,Adaptive!$4:$4,0),FALSE),0) -> 0 | T16: =IFERROR(VLOOKUP($E16,Adaptive!$A:$J,MATCH(T$8,Adaptive!$4:$4,0),FALSE),0) -> 0 | U16: =IFERROR(VLOOKUP($E16,Adaptive!$A:$J,MATCH(U$8,Adaptive!$4:$4,0),FALSE),0) -> 7998 | V16: =IFERROR(VLOOKUP($E16,Adaptive!$A:$J,MATCH(V$8,Adaptive!$4:$4,0),FALSE),0) -> 0 | W16: =IFERROR(VLOOKUP($E16,Adaptive!$A:$J,MATCH(W$8,Adaptive!$4:$4,0),FALSE),0) -> 0 | X16: =IFERROR(VLOOKUP($E16,Adaptive!$A:$J,MATCH(X$8,Adaptive!$4:$4,0),FALSE),0) -> 0 | Y16: =F16*700 -> 1785 | Z16: =_xlfn.XLOOKUP(B16,[1]Xref!$H:$H,[1]Xref!$A:$A) -> AU3426 Wide | AA16: =SUM(M16:P16) -> 0 | AB16: =ROUNDUP(AA16/Y16,0) -> 0 | AC16: =AB16-SUMPRODUCT(AE16:AL16,$AE$6:$AL$6) -> 0 | AM16: =SUMPRODUCT(AE16:AL16,$AE$6:$AL$6)*700 -> 0 | AN16: =AC16*700 -> 0
A17: 50 | B17: 228149 | C17: TR570B/NH900L/N BK/62 | D17: FF TR570B-39777-62 | E17: FF TR570B-39777-124 | F17: 1.9741935483870965 | G17: 1400 | I17: 5940 | J17: 1484 | K17: 0 | L17: 0 | M17: 4540 | N17: 1484 | O17: 0 | P17: 0 | Q17: =IFERROR(VLOOKUP($E17,Adaptive!$A:$J,MATCH(Q$8,Adaptive!$4:$4,0),FALSE),0) -> 0 | R17: =IFERROR(VLOOKUP($E17,Adaptive!$A:$J,MATCH(R$8,Adaptive!$4:$4,0),FALSE),0) -> 0 | S17: =IFERROR(VLOOKUP($E17,Adaptive!$A:$J,MATCH(S$8,Adaptive!$4:$4,0),FALSE),0) -> 0 | T17: =IFERROR(VLOOKUP($E17,Adaptive!$A:$J,MATCH(T$8,Adaptive!$4:$4,0),FALSE),0) -> 0 | U17: =IFERROR(VLOOKUP($E17,Adaptive!$A:$J,MATCH(U$8,Adaptive!$4:$4,0),FALSE),0) -> 0 | V17: =IFERROR(VLOOKUP($E17,Adaptive!$A:$J,MATCH(V$8,Adaptive!$4:$4,0),FALSE),0) -> 0 | W17: =IFERROR(VLOOKUP($E17,Adaptive!$A:$J,MATCH(W$8,Adaptive!$4:$4,0),FALSE),0) -> 0 | X17: =IFERROR(VLOOKUP($E17,Adaptive!$A:$J,MATCH(X$8,Adaptive!$4:$4,0),FALSE),0) -> 0 | Y17: =F17*700 -> 1381.9355 | Z17: =_xlfn.XLOOKUP(B17,[1]Xref!$H:$H,[1]Xref!$A:$A) -> AU4398 | AA17: =SUM(M17:P17) -> 6024 | AB17: =ROUNDUP(AA17/Y17,0) -> 5 | AC17: =AB17-SUMPRODUCT(AE17:AL17,$AE$6:$AL$6) -> 5 | AM17: =SUMPRODUCT(AE17:AL17,$AE$6:$AL$6)*700 -> 0 | AN17: =AC17*700 -> 3500
A18: 50 | B18: 228150 | C18: TR570B/NH836L/WS GR/62 | D18: FF TR570B-39226-62 | E18: FF TR570B-39226-124 | F18: 1.9741935483870965 | I18: 0 | J18: 0 | K18: 0 | L18: 72 | M18: 0 | N18: 0 | O18: 0 | P18: 0 | Q18: =IFERROR(VLOOKUP($E18,Adaptive!$A:$J,MATCH(Q$8,Adaptive!$4:$4,0),FALSE),0) -> 0 | R18: =IFERROR(VLOOKUP($E18,Adaptive!$A:$J,MATCH(R$8,Adaptive!$4:$4,0),FALSE),0) -> 0 | S18: =IFERROR(VLOOKUP($E18,Adaptive!$A:$J,MATCH(S$8,Adaptive!$4:$4,0),FALSE),0) -> 0 | T18: =IFERROR(VLOOKUP($E18,Adaptive!$A:$J,MATCH(T$8,Adaptive!$4:$4,0),FALSE),0) -> 0 | U18: =IFERROR(VLOOKUP($E18,Adaptive!$A:$J,MATCH(U$8,Adaptive!$4:$4,0),FALSE),0) -> 0 | V18: =IFERROR(VLOOKUP($E18,Adaptive!$A:$J,MATCH(V$8,Adaptive!$4:$4,0),FALSE),0) -> 0 | W18: =IFERROR(VLOOKUP($E18,Adaptive!$A:$J,MATCH(W$8,Adaptive!$4:$4,0),FALSE),0) -> 0 | X18: =IFERROR(VLOOKUP($E18,Adaptive!$A:$J,MATCH(X$8,Adaptive!$4:$4,0),FALSE),0) -> 0 | Y18: =F18*700 -> 1381.9355 | Z18: =_xlfn.XLOOKUP(B18,[1]Xref!$H:$H,[1]Xref!$A:$A) -> AU4398 | AA18: 0 | AB18: =ROUNDUP(AA18/Y18,0) -> 0 | AC18: =AB18-SUMPRODUCT(AE18:AL18,$AE$6:$AL$6) -> 0 | AM18: =SUMPRODUCT(AE18:AL18,$AE$6:$AL$6)*700 -> 0 | AN18: =AC18*700 -> 0
A19: 50 | B19: 228269 | C19: SPRUCE/149B/SHALE/67 | D19: FF SPRUCE-39433-67 | E19: FF SPRUCE-39433-134 | F19: 3.177157689811811 | G19: 1037 | H19: 7782 | I19: 5149 | J19: 0 | K19: 3465 | L19: 4095 | M19: 0 | N19: 0 | O19: 0 | P19: 3890 | Q19: =IFERROR(VLOOKUP($E19,Adaptive!$A:$J,MATCH(Q$8,Adaptive!$4:$4,0),FALSE),0) -> 7782 | R19: =IFERROR(VLOOKUP($E19,Adaptive!$A:$J,MATCH(R$8,Adaptive!$4:$4,0),FALSE),0) -> 0 | S19: =IFERROR(VLOOKUP($E19,Adaptive!$A:$J,MATCH(S$8,Adaptive!$4:$4,0),FALSE),0) -> 0 | T19: =IFERROR(VLOOKUP($E19,Adaptive!$A:$J,MATCH(T$8,Adaptive!$4:$4,0),FALSE),0) -> 0 | U19: =IFERROR(VLOOKUP($E19,Adaptive!$A:$J,MATCH(U$8,Adaptive!$4:$4,0),FALSE),0) -> 7782 | V19: =IFERROR(VLOOKUP($E19,Adaptive!$A:$J,MATCH(V$8,Adaptive!$4:$4,0),FALSE),0) -> 0 | W19: =IFERROR(VLOOKUP($E19,Adaptive!$A:$J,MATCH(W$8,Adaptive!$4:$4,0),FALSE),0) -> 0 | X19: =IFERROR(VLOOKUP($E19,Adaptive!$A:$J,MATCH(X$8,Adaptive!$4:$4,0),FALSE),0) -> 0 | Y19: =F19*700 -> 2224.0104 | Z19: =_xlfn.XLOOKUP(B19,[1]Xref!$H:$H,[1]Xref!$A:$A) -> AU1148G36 | AA19: =SUM(M19:P19) -> 3890 | AB19: =ROUNDUP(AA19/Y19,0) -> 2 | AC19: =AB19-SUMPRODUCT(AE19:AL19,$AE$6:$AL$6) -> 2 | AM19: =SUMPRODUCT(AE19:AL19,$AE$6:$AL$6)*700 -> 0 | AN19: =AC19*700 -> 1400
A20: 50 | B20: 228653 | C20: TR570B/NH900L/N BK/66 | D20: FF TR570B-39777-66 | E20: FF TR570B-39777-132 | F20: 1.8545454545454547 | G20: 777 | I20: 0 | J20: 612 | K20: 0 | L20: 636 | M20: 0 | N20: 0 | O20: 0 | P20: 471 | Q20: =IFERROR(VLOOKUP($E20,Adaptive!$A:$J,MATCH(Q$8,Adaptive!$4:$4,0),FALSE),0) -> 0 | R20: =IFERROR(VLOOKUP($E20,Adaptive!$A:$J,MATCH(R$8,Adaptive!$4:$4,0),FALSE),0) -> 0 | S20: =IFERROR(VLOOKUP($E20,Adaptive!$A:$J,MATCH(S$8,Adaptive!$4:$4,0),FALSE),0) -> 0 | T20: =IFERROR(VLOOKUP($E20,Adaptive!$A:$J,MATCH(T$8,Adaptive!$4:$4,0),FALSE),0) -> 0 | U20: =IFERROR(VLOOKUP($E20,Adaptive!$A:$J,MATCH(U$8,Adaptive!$4:$4,0),FALSE),0) -> 0 | V20: =IFERROR(VLOOKUP($E20,Adaptive!$A:$J,MATCH(V$8,Adaptive!$4:$4,0),FALSE),0) -> 0 | W20: =IFERROR(VLOOKUP($E20,Adaptive!$A:$J,MATCH(W$8,Adaptive!$4:$4,0),FALSE),0) -> 0 | X20: =IFERROR(VLOOKUP($E20,Adaptive!$A:$J,MATCH(X$8,Adaptive!$4:$4,0),FALSE),0) -> 0 | Y20: =F20*700 -> 1298.1818 | Z20: =_xlfn.XLOOKUP(B20,[1]Xref!$H:$H,[1]Xref!$A:$A) -> AU4398 | AA20: 0 | AB20: =ROUNDUP(AA20/Y20,0) -> 0 | AC20: =AB20-SUMPRODUCT(AE20:AL20,$AE$6:$AL$6) -> 0 | AM20: =SUMPRODUCT(AE20:AL20,$AE$6:$AL$6)*700 -> 0 | AN20: =AC20*700 -> 0
A21: 12 | B21: 228653A | C21: TR570BD/NH900L/N BK/66 | D21: FF TR570B-D-39777-66 | E21: FF TR570B-D-39777-132 | F21: 1.8545454545454547 | J21: 1417 | M21: 0 | N21: 1417 | Q21: =IFERROR(VLOOKUP($E21,Adaptive!$A:$J,MATCH(Q$8,Adaptive!$4:$4,0),FALSE),0) -> 0 | R21: =IFERROR(VLOOKUP($E21,Adaptive!$A:$J,MATCH(R$8,Adaptive!$4:$4,0),FALSE),0) -> 0 | S21: =IFERROR(VLOOKUP($E21,Adaptive!$A:$J,MATCH(S$8,Adaptive!$4:$4,0),FALSE),0) -> 0 | T21: =IFERROR(VLOOKUP($E21,Adaptive!$A:$J,MATCH(T$8,Adaptive!$4:$4,0),FALSE),0) -> 0 | U21: =IFERROR(VLOOKUP($E21,Adaptive!$A:$J,MATCH(U$8,Adaptive!$4:$4,0),FALSE),0) -> 0 | V21: =IFERROR(VLOOKUP($E21,Adaptive!$A:$J,MATCH(V$8,Adaptive!$4:$4,0),FALSE),0) -> 0 | W21: =IFERROR(VLOOKUP($E21,Adaptive!$A:$J,MATCH(W$8,Adaptive!$4:$4,0),FALSE),0) -> 0 | X21: =IFERROR(VLOOKUP($E21,Adaptive!$A:$J,MATCH(X$8,Adaptive!$4:$4,0),FALSE),0) -> 0 | Y21: =F21*700 -> 1298.1818 | Z21: =_xlfn.XLOOKUP(B21,[1]Xref!$H:$H,[1]Xref!$A:$A) -> AU7529 | AA21: =SUM(M21:P21) -> 1417 | AB21: =ROUNDUP(AA21/Y21,0) -> 2 | AC21: =AB21-SUMPRODUCT(AE21:AL21,$AE$6:$AL$6) -> 2 | AM21: =SUMPRODUCT(AE21:AL21,$AE$6:$AL$6)*700 -> 0 | AN21: =AC21*700 -> 1400
A22: 50 | B22: 228669 | C22: AU3426MSS/ME/LT GR/53 | D22: FF AU3426MSS-38840-53 | E22: FF AU3426MSS-38840-106 | F22: 3.0792452830188677 | I22: 0 | J22: 0 | K22: 242 | L22: 0 | M22: 0 | N22: 0 | O22: 242 | P22: 0 | Q22: =IFERROR(VLOOKUP($E22,Adaptive!$A:$J,MATCH(Q$8,Adaptive!$4:$4,0),FALSE),0) -> 0 | R22: =IFERROR(VLOOKUP($E22,Adaptive!$A:$J,MATCH(R$8,Adaptive!$4:$4,0),FALSE),0) -> 0 | S22: =IFERROR(VLOOKUP($E22,Adaptive!$A:$J,MATCH(S$8,Adaptive!$4:$4,0),FALSE),0) -> 0 | T22: =IFERROR(VLOOKUP($E22,Adaptive!$A:$J,MATCH(T$8,Adaptive!$4:$4,0),FALSE),0) -> 0 | U22: =IFERROR(VLOOKUP($E22,Adaptive!$A:$J,MATCH(U$8,Adaptive!$4:$4,0),FALSE),0) -> 0 | V22: =IFERROR(VLOOKUP($E22,Adaptive!$A:$J,MATCH(V$8,Adaptive!$4:$4,0),FALSE),0) -> 0 | W22: =IFERROR(VLOOKUP($E22,Adaptive!$A:$J,MATCH(W$8,Adaptive!$4:$4,0),FALSE),0) -> 0 | X22: =IFERROR(VLOOKUP($E22,Adaptive!$A:$J,MATCH(X$8,Adaptive!$4:$4,0),FALSE),0) -> 0 | Y22: =F22*700 -> 2155.4717 | Z22: =_xlfn.XLOOKUP(B22,[1]Xref!$H:$H,[1]Xref!$A:$A) -> AU3426 | AA22: =SUM(M22:P22) -> 242 | AB22: =ROUNDUP(AA22/Y22,0) -> 1 | AC22: =AB22-SUMPRODUCT(AE22:AL22,$AE$6:$AL$6) -> 1 | AM22: =SUMPRODUCT(AE22:AL22,$AE$6:$AL$6)*700 -> 0 | AN22: =AC22*700 -> 700
A23: 50 | B23: 229174 | C23: AU3426MSS/JC/BLACK/53 | D23: FF AU3426MSS-39858-53 | E23: FF AU3426MSS-39858-106 | F23: 3.0792452830188677 | I23: 0 | J23: 0 | K23: 0 | L23: 0 | M23: 0 | N23: 0 | O23: 0 | P23: 0 | Q23: =IFERROR(VLOOKUP($E23,Adaptive!$A:$J,MATCH(Q$8,Adaptive!$4:$4,0),FALSE),0) -> 0 | R23: =IFERROR(VLOOKUP($E23,Adaptive!$A:$J,MATCH(R$8,Adaptive!$4:$4,0),FALSE),0) -> 0 | S23: =IFERROR(VLOOKUP($E23,Adaptive!$A:$J,MATCH(S$8,Adaptive!$4:$4,0),FALSE),0) -> 0 | T23: =IFERROR(VLOOKUP($E23,Adaptive!$A:$J,MATCH(T$8,Adaptive!$4:$4,0),FALSE),0) -> 0 | U23: =IFERROR(VLOOKUP($E23,Adaptive!$A:$J,MATCH(U$8,Adaptive!$4:$4,0),FALSE),0) -> 0 | V23: =IFERROR(VLOOKUP($E23,Adaptive!$A:$J,MATCH(V$8,Adaptive!$4:$4,0),FALSE),0) -> 0 | W23: =IFERROR(VLOOKUP($E23,Adaptive!$A:$J,MATCH(W$8,Adaptive!$4:$4,0),FALSE),0) -> 0 | X23: =IFERROR(VLOOKUP($E23,Adaptive!$A:$J,MATCH(X$8,Adaptive!$4:$4,0),FALSE),0) -> 0 | Y23: =F23*700 -> 2155.4717 | Z23: =_xlfn.XLOOKUP(B23,[1]Xref!$H:$H,[1]Xref!$A:$A) -> AU3426 | AA23: =SUM(M23:P23) -> 0 | AB23: =ROUNDUP(AA23/Y23,0) -> 0 | AC23: =AB23-SUMPRODUCT(AE23:AL23,$AE$6:$AL$6) -> 0 | AM23: =SUMPRODUCT(AE23:AL23,$AE$6:$AL$6)*700 -> 0 | AN23: =AC23*700 -> 0
A24: 50 | B24: 229961 | C24: TR570B/NH882L/PL GR/48 | D24: FF TR570B-39789-48 | E24: FF TR570B-39789-144 | F24: 2.55 | G24: 2071 | I24: 5867 | J24: 12508 | K24: 0 | L24: 0 | M24: 3796 | N24: 12508 | O24: 0 | P24: 0 | Q24: =IFERROR(VLOOKUP($E24,Adaptive!$A:$J,MATCH(Q$8,Adaptive!$4:$4,0),FALSE),0) -> 0 | R24: =IFERROR(VLOOKUP($E24,Adaptive!$A:$J,MATCH(R$8,Adaptive!$4:$4,0),FALSE),0) -> 0 | S24: =IFERROR(VLOOKUP($E24,Adaptive!$A:$J,MATCH(S$8,Adaptive!$4:$4,0),FALSE),0) -> 0 | T24: =IFERROR(VLOOKUP($E24,Adaptive!$A:$J,MATCH(T$8,Adaptive!$4:$4,0),FALSE),0) -> 0 | U24: =IFERROR(VLOOKUP($E24,Adaptive!$A:$J,MATCH(U$8,Adaptive!$4:$4,0),FALSE),0) -> 0 | V24: =IFERROR(VLOOKUP($E24,Adaptive!$A:$J,MATCH(V$8,Adaptive!$4:$4,0),FALSE),0) -> 0 | W24: =IFERROR(VLOOKUP($E24,Adaptive!$A:$J,MATCH(W$8,Adaptive!$4:$4,0),FALSE),0) -> 0 | X24: =IFERROR(VLOOKUP($E24,Adaptive!$A:$J,MATCH(X$8,Adaptive!$4:$4,0),FALSE),0) -> 0 | Y24: =F24*700 -> 1785 | Z24: =_xlfn.XLOOKUP(B24,[1]Xref!$H:$H,[1]Xref!$A:$A) -> AU4398 | AA24: =SUM(M24:P24) -> 16304 | AB24: =ROUNDUP(AA24/Y24,0) -> 10 | AC24: =AB24-SUMPRODUCT(AE24:AL24,$AE$6:$AL$6) -> 10 | AM24: =SUMPRODUCT(AE24:AL24,$AE$6:$AL$6)*700 -> 0 | AN24: =AC24*700 -> 7000
A25: 50 | B25: 229962 | C25: TR570BSS/NH900L/NB/48 | D25: FF TR570B-39777-48 | E25: FF TR570B-39777-144 | F25: 2.55 | H25: 8400 | I25: 0 | J25: 5875 | K25: 0 | L25: 0 | M25: 0 | N25: 0 | O25: 0 | P25: 0 | Q25: =IFERROR(VLOOKUP($E25,Adaptive!$A:$J,MATCH(Q$8,Adaptive!$4:$4,0),FALSE),0) -> 0 | R25: =IFERROR(VLOOKUP($E25,Adaptive!$A:$J,MATCH(R$8,Adaptive!$4:$4,0),FALSE),0) -> 8400 | S25: =IFERROR(VLOOKUP($E25,Adaptive!$A:$J,MATCH(S$8,Adaptive!$4:$4,0),FALSE),0) -> 0 | T25: =IFERROR(VLOOKUP($E25,Adaptive!$A:$J,MATCH(T$8,Adaptive!$4:$4,0),FALSE),0) -> 0 | U25: =IFERROR(VLOOKUP($E25,Adaptive!$A:$J,MATCH(U$8,Adaptive!$4:$4,0),FALSE),0) -> 8400 | V25: =IFERROR(VLOOKUP($E25,Adaptive!$A:$J,MATCH(V$8,Adaptive!$4:$4,0),FALSE),0) -> 0 | W25: =IFERROR(VLOOKUP($E25,Adaptive!$A:$J,MATCH(W$8,Adaptive!$4:$4,0),FALSE),0) -> 0 | X25: =IFERROR(VLOOKUP($E25,Adaptive!$A:$J,MATCH(X$8,Adaptive!$4:$4,0),FALSE),0) -> 0 | Y25: =F25*700 -> 1785 | Z25: =_xlfn.XLOOKUP(B25,[1]Xref!$H:$H,[1]Xref!$A:$A) -> AU4398 | AA25: =SUM(M25:P25) -> 0 | AB25: =ROUNDUP(AA25/Y25,0) -> 0 | AC25: =AB25-SUMPRODUCT(AE25:AL25,$AE$6:$AL$6) -> 0 | AM25: =SUMPRODUCT(AE25:AL25,$AE$6:$AL$6)*700 -> 0 | AN25: =AC25*700 -> 0
A26: 50 | B26: 231553 | C26: ARCTICSS/600R/JT BK/73 | D26: FF ARCTIC-39811-73 | E26: FF ARCTIC-39811-146 | F26: 2.4840182648401825 | H26: 3300 | I26: 0 | J26: 3392 | K26: 0 | L26: 0 | M26: 0 | N26: 0 | O26: 0 | P26: 0 | Q26: =IFERROR(VLOOKUP($E26,Adaptive!$A:$J,MATCH(Q$8,Adaptive!$4:$4,0),FALSE),0) -> 0 | R26: =IFERROR(VLOOKUP($E26,Adaptive!$A:$J,MATCH(R$8,Adaptive!$4:$4,0),FALSE),0) -> 3300 | S26: =IFERROR(VLOOKUP($E26,Adaptive!$A:$J,MATCH(S$8,Adaptive!$4:$4,0),FALSE),0) -> 0 | T26: =IFERROR(VLOOKUP($E26,Adaptive!$A:$J,MATCH(T$8,Adaptive!$4:$4,0),FALSE),0) -> 0 | U26: =IFERROR(VLOOKUP($E26,Adaptive!$A:$J,MATCH(U$8,Adaptive!$4:$4,0),FALSE),0) -> 3300 | V26: =IFERROR(VLOOKUP($E26,Adaptive!$A:$J,MATCH(V$8,Adaptive!$4:$4,0),FALSE),0) -> 0 | W26: =IFERROR(VLOOKUP($E26,Adaptive!$A:$J,MATCH(W$8,Adaptive!$4:$4,0),FALSE),0) -> 0 | X26: =IFERROR(VLOOKUP($E26,Adaptive!$A:$J,MATCH(X$8,Adaptive!$4:$4,0),FALSE),0) -> 0 | Y26: =F26*700 -> 1738.8128 | Z26: =_xlfn.XLOOKUP(B26,[1]Xref!$H:$H,[1]Xref!$A:$A) -> AU5429D | AA26: =SUM(M26:P26) -> 0 | AB26: =ROUNDUP(AA26/Y26,0) -> 0 | AC26: =AB26-SUMPRODUCT(AE26:AL26,$AE$6:$AL$6) -> 0 | AM26: =SUMPRODUCT(AE26:AL26,$AE$6:$AL$6)*700 -> 0 | AN26: =AC26*700 -> 0
A27: 50 | B27: 232162 | C27: MESA/KZ67A/KZ67/45 | D27: FF MESASS-39833-45 | E27: FF MESASS-39833-135 | F27: 3.6266666666666665 | I27: 0 | J27: 1683 | K27: 0 | L27: 0 | M27: 0 | N27: 1683 | O27: 0 | P27: 0 | Q27: =IFERROR(VLOOKUP($E27,Adaptive!$A:$J,MATCH(Q$8,Adaptive!$4:$4,0),FALSE),0) -> 0 | R27: =IFERROR(VLOOKUP($E27,Adaptive!$A:$J,MATCH(R$8,Adaptive!$4:$4,0),FALSE),0) -> 0 | S27: =IFERROR(VLOOKUP($E27,Adaptive!$A:$J,MATCH(S$8,Adaptive!$4:$4,0),FALSE),0) -> 0 | T27: =IFERROR(VLOOKUP($E27,Adaptive!$A:$J,MATCH(T$8,Adaptive!$4:$4,0),FALSE),0) -> 0 | U27: =IFERROR(VLOOKUP($E27,Adaptive!$A:$J,MATCH(U$8,Adaptive!$4:$4,0),FALSE),0) -> 0 | V27: =IFERROR(VLOOKUP($E27,Adaptive!$A:$J,MATCH(V$8,Adaptive!$4:$4,0),FALSE),0) -> 0 | W27: =IFERROR(VLOOKUP($E27,Adaptive!$A:$J,MATCH(W$8,Adaptive!$4:$4,0),FALSE),0) -> 0 | X27: =IFERROR(VLOOKUP($E27,Adaptive!$A:$J,MATCH(X$8,Adaptive!$4:$4,0),FALSE),0) -> 0 | Y27: =F27*700 -> 2538.6667 | Z27: =_xlfn.XLOOKUP(B27,[1]Xref!$H:$H,[1]Xref!$A:$A) -> AU3426 | AA27: =SUM(M27:P27) -> 1683 | AB27: =ROUNDUP(AA27/Y27,0) -> 1 | AC27: =AB27-SUMPRODUCT(AE27:AL27,$AE$6:$AL$6) -> 1 | AM27: =SUMPRODUCT(AE27:AL27,$AE$6:$AL$6)*700 -> 0 | AN27: =AC27*700 -> 700
A28: 12 | B28: 232562 | C28: MOLTO/016B/LEX WHT/57 | D28: FF MOLTO-NA-40409-57 | E28: FF MOLTO-NA-40409-114 | F28: 1.8275475923852182 | M28: 0 | N28: 0 | O28: 0 | P28: 0 | Q28: =IFERROR(VLOOKUP($E28,Adaptive!$A:$J,MATCH(Q$8,Adaptive!$4:$4,0),FALSE),0) -> 0 | R28: =IFERROR(VLOOKUP($E28,Adaptive!$A:$J,MATCH(R$8,Adaptive!$4:$4,0),FALSE),0) -> 0 | S28: =IFERROR(VLOOKUP($E28,Adaptive!$A:$J,MATCH(S$8,Adaptive!$4:$4,0),FALSE),0) -> 0 | T28: =IFERROR(VLOOKUP($E28,Adaptive!$A:$J,MATCH(T$8,Adaptive!$4:$4,0),FALSE),0) -> 0 | U28: =IFERROR(VLOOKUP($E28,Adaptive!$A:$J,MATCH(U$8,Adaptive!$4:$4,0),FALSE),0) -> 0 | V28: =IFERROR(VLOOKUP($E28,Adaptive!$A:$J,MATCH(V$8,Adaptive!$4:$4,0),FALSE),0) -> 0 | W28: =IFERROR(VLOOKUP($E28,Adaptive!$A:$J,MATCH(W$8,Adaptive!$4:$4,0),FALSE),0) -> 0 | X28: =IFERROR(VLOOKUP($E28,Adaptive!$A:$J,MATCH(X$8,Adaptive!$4:$4,0),FALSE),0) -> 0 | Y28: =F28*700 -> 1279.2833 | Z28: =_xlfn.XLOOKUP(B28,[1]Xref!$H:$H,[1]Xref!$A:$A) -> AU6563 | AA28: =SUM(M28:P28) -> 0 | AB28: =ROUNDUP(AA28/Y28,0) -> 0 | AC28: =AB28-SUMPRODUCT(AE28:AL28,$AE$6:$AL$6) -> 0 | AM28: =SUMPRODUCT(AE28:AL28,$AE$6:$AL$6)*700 -> 0 | AN28: =AC28*700 -> 0
A29: 50 | B29: 232983 | C29: AURA30000/TX7/G BLK/68 | D29: FF AURA30000-40359-68 | E29: FF AURA30000-40359-136 | F29: 2.4 | G29: 11215 | H29: 14764 | I29: 10356 | J29: 12508 | K29: 5512 | L29: 37649 | M29: 0 | N29: 0 | O29: 2397 | P29: 37649 | Q29: =IFERROR(VLOOKUP($E29,Adaptive!$A:$J,MATCH(Q$8,Adaptive!$4:$4,0),FALSE),0) -> 0 | R29: =IFERROR(VLOOKUP($E29,Adaptive!$A:$J,MATCH(R$8,Adaptive!$4:$4,0),FALSE),0) -> 14764 | S29: =IFERROR(VLOOKUP($E29,Adaptive!$A:$J,MATCH(S$8,Adaptive!$4:$4,0),FALSE),0) -> 0 | T29: =IFERROR(VLOOKUP($E29,Adaptive!$A:$J,MATCH(T$8,Adaptive!$4:$4,0),FALSE),0) -> 0 | U29: =IFERROR(VLOOKUP($E29,Adaptive!$A:$J,MATCH(U$8,Adaptive!$4:$4,0),FALSE),0) -> 14764 | V29: =IFERROR(VLOOKUP($E29,Adaptive!$A:$J,MATCH(V$8,Adaptive!$4:$4,0),FALSE),0) -> 0 | W29: =IFERROR(VLOOKUP($E29,Adaptive!$A:$J,MATCH(W$8,Adaptive!$4:$4,0),FALSE),0) -> 0 | X29: =IFERROR(VLOOKUP($E29,Adaptive!$A:$J,MATCH(X$8,Adaptive!$4:$4,0),FALSE),0) -> 0 | Y29: =F29*700 -> 1680 | Z29: =_xlfn.XLOOKUP(B29,[1]Xref!$H:$H,[1]Xref!$A:$A) -> AU2958A | AA29: =SUM(M29:P29) -> 40046 | AB29: =ROUNDUP(AA29/Y29,0) -> 24 | AC29: =AB29-SUMPRODUCT(AE29:AL29,$AE$6:$AL$6) -> 24 | AM29: =SUMPRODUCT(AE29:AL29,$AE$6:$AL$6)*700 -> 0 | AN29: =AC29*700 -> 16800
A30: 12 | B30: 233117 | C30: MESA/KZ22A/PK82/62 | D30: FF MESA-39307-62 | E30: FF MESA-39307-124 | F30: 2.632258064516129 | G30: 2307 | I30: 3148 | J30: 1689 | M30: 841 | N30: 1689 | Q30: =IFERROR(VLOOKUP($E30,Adaptive!$A:$J,MATCH(Q$8,Adaptive!$4:$4,0),FALSE),0) -> 0 | R30: =IFERROR(VLOOKUP($E30,Adaptive!$A:$J,MATCH(R$8,Adaptive!$4:$4,0),FALSE),0) -> 0 | S30: =IFERROR(VLOOKUP($E30,Adaptive!$A:$J,MATCH(S$8,Adaptive!$4:$4,0),FALSE),0) -> 0 | T30: =IFERROR(VLOOKUP($E30,Adaptive!$A:$J,MATCH(T$8,Adaptive!$4:$4,0),FALSE),0) -> 0 | U30: =IFERROR(VLOOKUP($E30,Adaptive!$A:$J,MATCH(U$8,Adaptive!$4:$4,0),FALSE),0) -> 0 | V30: =IFERROR(VLOOKUP($E30,Adaptive!$A:$J,MATCH(V$8,Adaptive!$4:$4,0),FALSE),0) -> 0 | W30: =IFERROR(VLOOKUP($E30,Adaptive!$A:$J,MATCH(W$8,Adaptive!$4:$4,0),FALSE),0) -> 0 | X30: =IFERROR(VLOOKUP($E30,Adaptive!$A:$J,MATCH(X$8,Adaptive!$4:$4,0),FALSE),0) -> 0 | Y30: =F30*700 -> 1842.5806 | Z30: =_xlfn.XLOOKUP(B30,[1]Xref!$H:$H,[1]Xref!$A:$A) -> AU3426A | AA30: =SUM(M30:P30) -> 2530 | AB30: =ROUNDUP(AA30/Y30,0) -> 2 | AC30: =AB30-SUMPRODUCT(AE30:AL30,$AE$6:$AL$6) -> 2 | AM30: =SUMPRODUCT(AE30:AL30,$AE$6:$AL$6)*700 -> 0 | AN30: =AC30*700 -> 1400
A31: 50 | B31: 233169 | C31: MESA/KZ67A/KZ67/58 | D31: FF MESA-39327-58 | E31: FF MESA-39327-116 | F31: 2.8137931034482753 | G31: 11816 | I31: 9492 | J31: 0 | K31: 0 | L31: 0 | M31: 0 | N31: 0 | O31: 0 | P31: 0 | Q31: =IFERROR(VLOOKUP($E31,Adaptive!$A:$J,MATCH(Q$8,Adaptive!$4:$4,0),FALSE),0) -> 0 | R31: =IFERROR(VLOOKUP($E31,Adaptive!$A:$J,MATCH(R$8,Adaptive!$4:$4,0),FALSE),0) -> 0 | S31: =IFERROR(VLOOKUP($E31,Adaptive!$A:$J,MATCH(S$8,Adaptive!$4:$4,0),FALSE),0) -> 0 | T31: =IFERROR(VLOOKUP($E31,Adaptive!$A:$J,MATCH(T$8,Adaptive!$4:$4,0),FALSE),0) -> 0 | U31: =IFERROR(VLOOKUP($E31,Adaptive!$A:$J,MATCH(U$8,Adaptive!$4:$4,0),FALSE),0) -> 0 | V31: =IFERROR(VLOOKUP($E31,Adaptive!$A:$J,MATCH(V$8,Adaptive!$4:$4,0),FALSE),0) -> 0 | W31: =IFERROR(VLOOKUP($E31,Adaptive!$A:$J,MATCH(W$8,Adaptive!$4:$4,0),FALSE),0) -> 0 | X31: =IFERROR(VLOOKUP($E31,Adaptive!$A:$J,MATCH(X$8,Adaptive!$4:$4,0),FALSE),0) -> 0 | Y31: =F31*700 -> 1969.6552 | Z31: =_xlfn.XLOOKUP(B31,[1]Xref!$H:$H,[1]Xref!$A:$A) -> AU3426 | AA31: =SUM(M31:P31) -> 0 | AB31: =ROUNDUP(AA31/Y31,0) -> 0 | AC31: =AB31-SUMPRODUCT(AE31:AL31,$AE$6:$AL$6) -> 0 | AM31: =SUMPRODUCT(AE31:AL31,$AE$6:$AL$6)*700 -> 0 | AN31: =AC31*700 -> 0
A32: 50 | B32: 233981 | C32: ARCTICSS/999K/DAGR/73 | D32: FF ARCTIC-40416-73 | E32: FF ARCTIC-40416-146 | F32: 2.4840182648401825 | G32: 2080 | I32: 756 | J32: 1908 | K32: 0 | L32: 954 | M32: 0 | N32: 584 | O32: 0 | P32: 954 | Q32: =IFERROR(VLOOKUP($E32,Adaptive!$A:$J,MATCH(Q$8,Adaptive!$4:$4,0),FALSE),0) -> 0 | R32: =IFERROR(VLOOKUP($E32,Adaptive!$A:$J,MATCH(R$8,Adaptive!$4:$4,0),FALSE),0) -> 0 | S32: =IFERROR(VLOOKUP($E32,Adaptive!$A:$J,MATCH(S$8,Adaptive!$4:$4,0),FALSE),0) -> 0 | T32: =IFERROR(VLOOKUP($E32,Adaptive!$A:$J,MATCH(T$8,Adaptive!$4:$4,0),FALSE),0) -> 0 | U32: =IFERROR(VLOOKUP($E32,Adaptive!$A:$J,MATCH(U$8,Adaptive!$4:$4,0),FALSE),0) -> 0 | V32: =IFERROR(VLOOKUP($E32,Adaptive!$A:$J,MATCH(V$8,Adaptive!$4:$4,0),FALSE),0) -> 0 | W32: =IFERROR(VLOOKUP($E32,Adaptive!$A:$J,MATCH(W$8,Adaptive!$4:$4,0),FALSE),0) -> 0 | X32: =IFERROR(VLOOKUP($E32,Adaptive!$A:$J,MATCH(X$8,Adaptive!$4:$4,0),FALSE),0) -> 0 | Y32: =F32*700 -> 1738.8128 | Z32: =_xlfn.XLOOKUP(B32,[1]Xref!$H:$H,[1]Xref!$A:$A) -> AU5429D | AA32: =SUM(M32:P32) -> 1538 | AB32: =ROUNDUP(AA32/Y32,0) -> 1 | AC32: =AB32-SUMPRODUCT(AE32:AL32,$AE$6:$AL$6) -> 1 | AM32: =SUMPRODUCT(AE32:AL32,$AE$6:$AL$6)*700 -> 0 | AN32: =AC32*700 -> 700
A33: 50 | B33: 233982 | C33: ARCTICSS/309X/VDA/73 | D33: FF ARCTIC-40415-73 | E33: FF ARCTIC-40415-146 | F33: 2.4840182648401825 | I33: 0 | J33: 0 | K33: 0 | L33: 0 | M33: 0 | N33: 0 | O33: 0 | P33: 0 | Q33: =IFERROR(VLOOKUP($E33,Adaptive!$A:$J,MATCH(Q$8,Adaptive!$4:$4,0),FALSE),0) -> 0 | R33: =IFERROR(VLOOKUP($E33,Adaptive!$A:$J,MATCH(R$8,Adaptive!$4:$4,0),FALSE),0) -> 0 | S33: =IFERROR(VLOOKUP($E33,Adaptive!$A:$J,MATCH(S$8,Adaptive!$4:$4,0),FALSE),0) -> 0 | T33: =IFERROR(VLOOKUP($E33,Adaptive!$A:$J,MATCH(T$8,Adaptive!$4:$4,0),FALSE),0) -> 0 | U33: =IFERROR(VLOOKUP($E33,Adaptive!$A:$J,MATCH(U$8,Adaptive!$4:$4,0),FALSE),0) -> 0 | V33: =IFERROR(VLOOKUP($E33,Adaptive!$A:$J,MATCH(V$8,Adaptive!$4:$4,0),FALSE),0) -> 0 | W33: =IFERROR(VLOOKUP($E33,Adaptive!$A:$J,MATCH(W$8,Adaptive!$4:$4,0),FALSE),0) -> 0 | X33: =IFERROR(VLOOKUP($E33,Adaptive!$A:$J,MATCH(X$8,Adaptive!$4:$4,0),FALSE),0) -> 0 | Y33: =F33*700 -> 1738.8128 | Z33: =_xlfn.XLOOKUP(B33,[1]Xref!$H:$H,[1]Xref!$A:$A) -> AU5429D | AA33: =SUM(M33:P33) -> 0 | AB33: =ROUNDUP(AA33/Y33,0) -> 0 | AC33: =AB33-SUMPRODUCT(AE33:AL33,$AE$6:$AL$6) -> 0 | AM33: =SUMPRODUCT(AE33:AL33,$AE$6:$AL$6)*700 -> 0 | AN33: =AC33*700 -> 0
A34: 50 | B34: 234060 | C34: TAFFETA/PACCAR GRAY/50 | D34: FF TAFFETAHP-39869-50 | E34: FF TAFFETAHP-39869-150 | F34: 2.72 | I34: 0 | J34: 0 | K34: 0 | L34: 1936 | M34: 0 | N34: 0 | O34: 0 | P34: 1936 | Q34: =IFERROR(VLOOKUP($E34,Adaptive!$A:$J,MATCH(Q$8,Adaptive!$4:$4,0),FALSE),0) -> 0 | R34: =IFERROR(VLOOKUP($E34,Adaptive!$A:$J,MATCH(R$8,Adaptive!$4:$4,0),FALSE),0) -> 0 | S34: =IFERROR(VLOOKUP($E34,Adaptive!$A:$J,MATCH(S$8,Adaptive!$4:$4,0),FALSE),0) -> 0 | T34: =IFERROR(VLOOKUP($E34,Adaptive!$A:$J,MATCH(T$8,Adaptive!$4:$4,0),FALSE),0) -> 0 | U34: =IFERROR(VLOOKUP($E34,Adaptive!$A:$J,MATCH(U$8,Adaptive!$4:$4,0),FALSE),0) -> 0 | V34: =IFERROR(VLOOKUP($E34,Adaptive!$A:$J,MATCH(V$8,Adaptive!$4:$4,0),FALSE),0) -> 0 | W34: =IFERROR(VLOOKUP($E34,Adaptive!$A:$J,MATCH(W$8,Adaptive!$4:$4,0),FALSE),0) -> 0 | X34: =IFERROR(VLOOKUP($E34,Adaptive!$A:$J,MATCH(X$8,Adaptive!$4:$4,0),FALSE),0) -> 0 | Y34: =F34*700 -> 1904 | Z34: =_xlfn.XLOOKUP(B34,[1]Xref!$H:$H,[1]Xref!$A:$A) -> AU4583 210 | AA34: =SUM(M34:P34) -> 1936 | AB34: =ROUNDUP(AA34/Y34,0) -> 2 | AC34: =AB34-SUMPRODUCT(AE34:AL34,$AE$6:$AL$6) -> 2 | AM34: =SUMPRODUCT(AE34:AL34,$AE$6:$AL$6)*700 -> 0 | AN34: =AC34*700 -> 1400
A35: 50 | B35: 234794 | C35: TAFFETA/600R/JT BLK/67 | D35: FF TAFFETAHP-38712-67 | E35: FF TAFFETAHP-38712-134 | F35: 2.0298507462686564 | G35: 304 | I35: 1020 | J35: 0 | K35: 6254 | L35: 0 | M35: 716 | N35: 0 | O35: 6254 | P35: 0 | Q35: =IFERROR(VLOOKUP($E35,Adaptive!$A:$J,MATCH(Q$8,Adaptive!$4:$4,0),FALSE),0) -> 0 | R35: =IFERROR(VLOOKUP($E35,Adaptive!$A:$J,MATCH(R$8,Adaptive!$4:$4,0),FALSE),0) -> 0 | S35: =IFERROR(VLOOKUP($E35,Adaptive!$A:$J,MATCH(S$8,Adaptive!$4:$4,0),FALSE),0) -> 0 | T35: =IFERROR(VLOOKUP($E35,Adaptive!$A:$J,MATCH(T$8,Adaptive!$4:$4,0),FALSE),0) -> 0 | U35: =IFERROR(VLOOKUP($E35,Adaptive!$A:$J,MATCH(U$8,Adaptive!$4:$4,0),FALSE),0) -> 0 | V35: =IFERROR(VLOOKUP($E35,Adaptive!$A:$J,MATCH(V$8,Adaptive!$4:$4,0),FALSE),0) -> 0 | W35: =IFERROR(VLOOKUP($E35,Adaptive!$A:$J,MATCH(W$8,Adaptive!$4:$4,0),FALSE),0) -> 0 | X35: =IFERROR(VLOOKUP($E35,Adaptive!$A:$J,MATCH(X$8,Adaptive!$4:$4,0),FALSE),0) -> 0 | Y35: =F35*700 -> 1420.8955 | Z35: =_xlfn.XLOOKUP(B35,[1]Xref!$H:$H,[1]Xref!$A:$A) -> AU4583 | AA35: =SUM(M35:P35) -> 6970 | AB35: =ROUNDUP(AA35/Y35,0) -> 5 | AC35: =AB35-SUMPRODUCT(AE35:AL35,$AE$6:$AL$6) -> 5 | AM35: =SUMPRODUCT(AE35:AL35,$AE$6:$AL$6)*700 -> 0 | AN35: =AC35*700 -> 3500
A36: 50 | B36: 234795 | C36: ARCTIC/600R/JT BLK/68 | D36: FF ARCTIC-39811-68 | E36: FF ARCTIC-39811-136 | F36: 2.666666666666666 | G36: 1573 | H36: 19122 | I36: 0 | J36: 20662 | K36: 0 | L36: 25970 | M36: 0 | N36: 0 | O36: 0 | P36: 25937 | Q36: =IFERROR(VLOOKUP($E36,Adaptive!$A:$J,MATCH(Q$8,Adaptive!$4:$4,0),FALSE),0) -> 10822 | R36: =IFERROR(VLOOKUP($E36,Adaptive!$A:$J,MATCH(R$8,Adaptive!$4:$4,0),FALSE),0) -> 0 | S36: =IFERROR(VLOOKUP($E36,Adaptive!$A:$J,MATCH(S$8,Adaptive!$4:$4,0),FALSE),0) -> 8300 | T36: =IFERROR(VLOOKUP($E36,Adaptive!$A:$J,MATCH(T$8,Adaptive!$4:$4,0),FALSE),0) -> 0 | U36: =IFERROR(VLOOKUP($E36,Adaptive!$A:$J,MATCH(U$8,Adaptive!$4:$4,0),FALSE),0) -> 19122 | V36: =IFERROR(VLOOKUP($E36,Adaptive!$A:$J,MATCH(V$8,Adaptive!$4:$4,0),FALSE),0) -> 0 | W36: =IFERROR(VLOOKUP($E36,Adaptive!$A:$J,MATCH(W$8,Adaptive!$4:$4,0),FALSE),0) -> 0 | X36: =IFERROR(VLOOKUP($E36,Adaptive!$A:$J,MATCH(X$8,Adaptive!$4:$4,0),FALSE),0) -> 0 | Y36: =F36*700 -> 1866.6667 | Z36: =_xlfn.XLOOKUP(B36,[1]Xref!$H:$H,[1]Xref!$A:$A) -> AU5429D | AA36: =SUM(M36:P36) -> 25937 | AB36: =ROUNDUP(AA36/Y36,0) -> 14 | AC36: =AB36-SUMPRODUCT(AE36:AL36,$AE$6:$AL$6) -> 14 | AM36: =SUMPRODUCT(AE36:AL36,$AE$6:$AL$6)*700 -> 0 | AN36: =AC36*700 -> 9800
A37: 50 | B37: 234918 | C37: AU5429D/GRAYSTONE/63 | D37: FF ARCTIC-40506-63 | E37: FF ARCTIC-40506-126 | F37: 2.878306878306878 | H37: 2202 | I37: 0 | J37: 843 | K37: 0 | L37: 0 | M37: 0 | N37: 0 | O37: 0 | P37: 0 | Q37: =IFERROR(VLOOKUP($E37,Adaptive!$A:$J,MATCH(Q$8,Adaptive!$4:$4,0),FALSE),0) -> 0 | R37: =IFERROR(VLOOKUP($E37,Adaptive!$A:$J,MATCH(R$8,Adaptive!$4:$4,0),FALSE),0) -> 2202 | S37: =IFERROR(VLOOKUP($E37,Adaptive!$A:$J,MATCH(S$8,Adaptive!$4:$4,0),FALSE),0) -> 0 | T37: =IFERROR(VLOOKUP($E37,Adaptive!$A:$J,MATCH(T$8,Adaptive!$4:$4,0),FALSE),0) -> 0 | U37: =IFERROR(VLOOKUP($E37,Adaptive!$A:$J,MATCH(U$8,Adaptive!$4:$4,0),FALSE),0) -> 2202 | V37: =IFERROR(VLOOKUP($E37,Adaptive!$A:$J,MATCH(V$8,Adaptive!$4:$4,0),FALSE),0) -> 0 | W37: =IFERROR(VLOOKUP($E37,Adaptive!$A:$J,MATCH(W$8,Adaptive!$4:$4,0),FALSE),0) -> 0 | X37: =IFERROR(VLOOKUP($E37,Adaptive!$A:$J,MATCH(X$8,Adaptive!$4:$4,0),FALSE),0) -> 0 | Y37: =F37*700 -> 2014.8148 | Z37: =_xlfn.XLOOKUP(B37,[1]Xref!$H:$H,[1]Xref!$A:$A) -> AU5429D | AA37: =SUM(M37:P37) -> 0 | AB37: =ROUNDUP(AA37/Y37,0) -> 0 | AC37: =AB37-SUMPRODUCT(AE37:AL37,$AE$6:$AL$6) -> 0 | AM37: =SUMPRODUCT(AE37:AL37,$AE$6:$AL$6)*700 -> 0 | AN37: =AC37*700 -> 0
A38: 12 | B38: 235397 | C38: MESA/KG0R/BLACK/62 | D38: FF MESA-40241-62 | E38: FF MESA-40241-124 | F38: 2.632258064516129 | G38: 2248 | I38: 1239 | J38: 440 | M38: 0 | N38: 0 | O38: 0 | P38: 0 | Q38: =IFERROR(VLOOKUP($E38,Adaptive!$A:$J,MATCH(Q$8,Adaptive!$4:$4,0),FALSE),0) -> 0 | R38: =IFERROR(VLOOKUP($E38,Adaptive!$A:$J,MATCH(R$8,Adaptive!$4:$4,0),FALSE),0) -> 0 | S38: =IFERROR(VLOOKUP($E38,Adaptive!$A:$J,MATCH(S$8,Adaptive!$4:$4,0),FALSE),0) -> 0 | T38: =IFERROR(VLOOKUP($E38,Adaptive!$A:$J,MATCH(T$8,Adaptive!$4:$4,0),FALSE),0) -> 0 | U38: =IFERROR(VLOOKUP($E38,Adaptive!$A:$J,MATCH(U$8,Adaptive!$4:$4,0),FALSE),0) -> 0 | V38: =IFERROR(VLOOKUP($E38,Adaptive!$A:$J,MATCH(V$8,Adaptive!$4:$4,0),FALSE),0) -> 0 | W38: =IFERROR(VLOOKUP($E38,Adaptive!$A:$J,MATCH(W$8,Adaptive!$4:$4,0),FALSE),0) -> 0 | X38: =IFERROR(VLOOKUP($E38,Adaptive!$A:$J,MATCH(X$8,Adaptive!$4:$4,0),FALSE),0) -> 0 | Y38: =F38*700 -> 1842.5806 | Z38: =_xlfn.XLOOKUP(B38,[1]Xref!$H:$H,[1]Xref!$A:$A) -> AU3426 | AA38: =SUM(M38:P38) -> 0 | AB38: =ROUNDUP(AA38/Y38,0) -> 0 | AC38: =AB38-SUMPRODUCT(AE38:AL38,$AE$6:$AL$6) -> 0 | AM38: =SUMPRODUCT(AE38:AL38,$AE$6:$AL$6)*700 -> 0 | AN38: =AC38*700 -> 0
A39: 50 | B39: 236592 | C39: ARCTIC/308X/V DK AT/68 | D39: FF ARCTIC-40415-68 | E39: FF ARCTIC-40415-136 | F39: 2.666666666666666 | G39: 297 | I39: 0 | J39: 0 | K39: 0 | L39: 575 | M39: 0 | N39: 0 | O39: 0 | P39: 0 | Q39: =IFERROR(VLOOKUP($E39,Adaptive!$A:$J,MATCH(Q$8,Adaptive!$4:$4,0),FALSE),0) -> 0 | R39: =IFERROR(VLOOKUP($E39,Adaptive!$A:$J,MATCH(R$8,Adaptive!$4:$4,0),FALSE),0) -> 0 | S39: =IFERROR(VLOOKUP($E39,Adaptive!$A:$J,MATCH(S$8,Adaptive!$4:$4,0),FALSE),0) -> 0 | T39: =IFERROR(VLOOKUP($E39,Adaptive!$A:$J,MATCH(T$8,Adaptive!$4:$4,0),FALSE),0) -> 0 | U39: =IFERROR(VLOOKUP($E39,Adaptive!$A:$J,MATCH(U$8,Adaptive!$4:$4,0),FALSE),0) -> 0 | V39: =IFERROR(VLOOKUP($E39,Adaptive!$A:$J,MATCH(V$8,Adaptive!$4:$4,0),FALSE),0) -> 0 | W39: =IFERROR(VLOOKUP($E39,Adaptive!$A:$J,MATCH(W$8,Adaptive!$4:$4,0),FALSE),0) -> 0 | X39: =IFERROR(VLOOKUP($E39,Adaptive!$A:$J,MATCH(X$8,Adaptive!$4:$4,0),FALSE),0) -> 0 | Y39: =F39*700 -> 1866.6667 | Z39: =_xlfn.XLOOKUP(B39,[1]Xref!$H:$H,[1]Xref!$A:$A) -> AU5429D | AA39: =SUM(M39:P39) -> 0 | AB39: =ROUNDUP(AA39/Y39,0) -> 0 | AC39: =AB39-SUMPRODUCT(AE39:AL39,$AE$6:$AL$6) -> 0 | AM39: =SUMPRODUCT(AE39:AL39,$AE$6:$AL$6)*700 -> 0 | AN39: =AC39*700 -> 0
A40: 50 | B40: 237033 | C40: TAFFETA/309X/VDKATM/67 | D40: FF TAFFETAHP-40512-67 | E40: FF TAFFETAHP-40512-134 | F40: 2.0298507462686564 | I40: 0 | J40: 0 | K40: 742 | L40: 0 | M40: 0 | N40: 0 | O40: 742 | P40: 0 | Q40: =IFERROR(VLOOKUP($E40,Adaptive!$A:$J,MATCH(Q$8,Adaptive!$4:$4,0),FALSE),0) -> 0 | R40: =IFERROR(VLOOKUP($E40,Adaptive!$A:$J,MATCH(R$8,Adaptive!$4:$4,0),FALSE),0) -> 0 | S40: =IFERROR(VLOOKUP($E40,Adaptive!$A:$J,MATCH(S$8,Adaptive!$4:$4,0),FALSE),0) -> 0 | T40: =IFERROR(VLOOKUP($E40,Adaptive!$A:$J,MATCH(T$8,Adaptive!$4:$4,0),FALSE),0) -> 0 | U40: =IFERROR(VLOOKUP($E40,Adaptive!$A:$J,MATCH(U$8,Adaptive!$4:$4,0),FALSE),0) -> 0 | V40: =IFERROR(VLOOKUP($E40,Adaptive!$A:$J,MATCH(V$8,Adaptive!$4:$4,0),FALSE),0) -> 0 | W40: =IFERROR(VLOOKUP($E40,Adaptive!$A:$J,MATCH(W$8,Adaptive!$4:$4,0),FALSE),0) -> 0 | X40: =IFERROR(VLOOKUP($E40,Adaptive!$A:$J,MATCH(X$8,Adaptive!$4:$4,0),FALSE),0) -> 0 | Y40: =F40*700 -> 1420.8955 | Z40: =_xlfn.XLOOKUP(B40,[1]Xref!$H:$H,[1]Xref!$A:$A) -> AU4583 | AA40: =SUM(M40:P40) -> 742 | AB40: =ROUNDUP(AA40/Y40,0) -> 1 | AC40: =AB40-SUMPRODUCT(AE40:AL40,$AE$6:$AL$6) -> 1 | AM40: =SUMPRODUCT(AE40:AL40,$AE$6:$AL$6)*700 -> 0 | AN40: =AC40*700 -> 700
...

Sheet Adaptive
A3: Sum of Adaptive Qty | B3: Column Labels
A4: Row Labels | B4: 45882 | C4: 45883 | D4: 45884 | E4: 45887 | F4: Grand Total
A5: FF ANMUT-C-NA-40487-132 | E5: 6808 | F5: 6808
A6: FF ANMUT-C-NA-40488-132 | C6: 6760 | F6: 6760
A7: FF ARCTIC-39811-136 | B7: 10822 | D7: 8300 | F7: 19122
A8: FF ARCTIC-39811-146 | C8: 3300 | F8: 3300
A9: FF ARCTIC-40506-126 | C9: 2202 | F9: 2202
A10: FF AU3426M-38840-128 | C10: 7998 | F10: 7998
A11: FF AURA30000-40359-136 | C11: 14764 | F11: 14764
A12: FF LYRICHELHS-41114-126 | C12: 7750 | F12: 7750
A13: FF LYRICP-40542-110 | C13: 2200 | F13: 2200
A14: FF LYRICRSS-40582-128 | C14: 1830 | F14: 1830
A15: FF MESA-39307-126 | B15: 4050 | C15: 10110 | F15: 14160
A16: FF MESA-40241-126 | C16: 2100 | F16: 2100
A17: FF MOLTO-NA-40383-118 | B17: 5000 | E17: 6198 | F17: 11198
A18: FF MOLTO-NA-41256-128 | C18: 2500 | F18: 2500
A19: FF MOLTOX-NA-40771-124 | B19: 1500 | F19: 1500
A20: FF PROVT-NDWR-40973-122 | B20: 5966 | C20: 11932 | F20: 17898
A21: FF SPRUCE-39433-134 | B21: 7782 | F21: 7782
A22: FF TAFFETAHP-41026-134 | B22: 1950 | F22: 1950
A23: FF TR570B-39777-144 | C23: 8400 | F23: 8400
A24: FF TR665B-40477-130 | C24: 1650 | F24: 1650
A25: FF TR665B-40478-130 | D25: 1902 | F25: 1902
A26: FF TR684B-40610-120 | D26: 17016 | E26: 8508 | F26: 25524
A27: Grand Total | B27: 37070 | C27: 83496 | D27: 27218 | E27: 21514 | F27: 169298
